Workbook

Sheet Ввод
A1: Портфель на 24 месяца: работа + бот на крипте
A2: Жёлтые ячейки можно менять. Лист «Месяцы» пересчитается сам. Цифры доходности — твой сценарий, не обещание рынка. Срез цен: лист «Примеры сегодня».
A4: Откуда деньги
A5: Откладываю с работы каждый месяц | C5: 20000
A6: Старт бота на крипте | C6: 100000
A7: Прибыль бота за месяц | C7: 0.05 | D7: Смени, например, на 3% или 10% — итог справа обновится.
A8: Какую долю прибыли снимаем с бота | C8: 0.2
A9: Дата старта | C9: 46266
A11: Куда кладём снятое с бота и 20 тысяч с работы (сумма долей = 100%)
A12: Спокойный вклад | C12: 0.4
A13: Облигации государства / фонды почти как вклад | C13: 0.15
A14: Акции компаний (лучше фонд на индекс, не одна бумага) | C14: 0.2
A15: Золото | C15: 0.15
A16: Биткоин (уже вне бота, без займа) | C16: 0.1
A17: Сумма долей (должно быть 100%) | C17: =C12+C13+C14+C15+C16 | D17: =IF(ABS(C17-1)<0.0001,"норм","поправь доли: сумма не 100%")
A19: Какой рост за год закладываем в расчёт (меняй под свой сценарий)
A20: Вклад, % за год | C20: 0.14 | E20: за месяц | F20: =(1+C20)^(1/12)-1
A21: Облигации / фонды почти как вклад, % за год | C21: 0.135 | E21: за месяц | F21: =(1+C21)^(1/12)-1
A22: Акции компаний, % за год | C22: 0.12 | E22: за месяц | F22: =(1+C22)^(1/12)-1
A23: Золото, % за год | C23: 0.08 | E23: за месяц | F23: =(1+C23)^(1/12)-1
A24: Биткоин вне бота, % за год | C24: 0.3 | E24: за месяц | F24: =(1+C24)^(1/12)-1
A26: Сколько нужно на машину (из проекта, запас 10%)
A27: Вторичка с российским паспортом | C27: 3990000
A28: Салон, новая базовая | C28: 5720000
A30: Итог через 24 месяца
A31: На боте | C31: =Месяцы!F26
A32: Во вкладе | C32: =Месяцы!I26
A33: В облигациях / фондах почти как вклад | C33: =Месяцы!J26
A34: В акциях | C34: =Месяцы!K26
A35: В золоте | C35: =Месяцы!L26
A36: В биткоине (вне бота) | C36: =Месяцы!M26
A37: Портфель рядом (всё кроме бота) | C37: =C32+C33+C34+C35+C36
A38: Всего денег | C38: =C31+C37
A40: Хватает ли на машину? | C40: =IF(C38>=C28,"да, на салон",IF(C38>=C27,"да, на вторичку","нет"))
A42: 5% в месяц у бота — уже очень сильный сценарий. 21% в месяц два года подряд в проекте считается нереалистичным. Смотри docs/fuchersy-bot.md.

Sheet Месяцы
A1: Месяц | B1: Дата | C1: Бот на начало | D1: Прибыль бота | E1: Сняли 20% прибыли | F1: Бот на конец | G1: С работы | H1: Всего в портфель рядом | I1: Вклад | J1: Облигации / фонды | K1: Акции | L1: Золото | M1: Биткоин вне бота | N1: Портфель рядом | O1: Всего
A2: 0 | B2: =Ввод!C9 | C2: 0 | D2: 0 | E2: 0 | F2: =Ввод!C6 | G2: 0 | H2: 0 | I2: 0 | J2: 0 | K2: 0 | L2: 0 | M2: 0 | N2: =I2+J2+K2+L2+M2 | O2: =F2+N2
A3: 1 | B3: =EDATE($B$2,A3) | C3: =F2 | D3: =C3*Ввод!$C$7 | E3: =IF(D3>0,D3*Ввод!$C$8,0) | F3: =C3+D3-E3 | G3: =Ввод!$C$5 | H3: =E3+G3 | I3: =I2*(1+Ввод!$F$20)+H3*Ввод!$C$12 | J3: =J2*(1+Ввод!$F$21)+H3*Ввод!$C$13 | K3: =K2*(1+Ввод!$F$22)+H3*Ввод!$C$14 | L3: =L2*(1+Ввод!$F$23)+H3*Ввод!$C$15 | M3: =M2*(1+Ввод!$F$24)+H3*Ввод!$C$16 | N3: =I3+J3+K3+L3+M3 | O3: =F3+N3
A4: 2 | B4: =EDATE($B$2,A4) | C4: =F3 | D4: =C4*Ввод!$C$7 | E4: =IF(D4>0,D4*Ввод!$C$8,0) | F4: =C4+D4-E4 | G4: =Ввод!$C$5 | H4: =E4+G4 | I4: =I3*(1+Ввод!$F$20)+H4*Ввод!$C$12 | J4: =J3*(1+Ввод!$F$21)+H4*Ввод!$C$13 | K4: =K3*(1+Ввод!$F$22)+H4*Ввод!$C$14 | L4: =L3*(1+Ввод!$F$23)+H4*Ввод!$C$15 | M4: =M3*(1+Ввод!$F$24)+H4*Ввод!$C$16 | N4: =I4+J4+K4+L4+M4 | O4: =F4+N4
A5: 3 | B5: =EDATE($B$2,A5) | C5: =F4 | D5: =C5*Ввод!$C$7 | E5: =IF(D5>0,D5*Ввод!$C$8,0) | F5: =C5+D5-E5 | G5: =Ввод!$C$5 | H5: =E5+G5 | I5: =I4*(1+Ввод!$F$20)+H5*Ввод!$C$12 | J5: =J4*(1+Ввод!$F$21)+H5*Ввод!$C$13 | K5: =K4*(1+Ввод!$F$22)+H5*Ввод!$C$14 | L5: =L4*(1+Ввод!$F$23)+H5*Ввод!$C$15 | M5: =M4*(1+Ввод!$F$24)+H5*Ввод!$C$16 | N5: =I5+J5+K5+L5+M5 | O5: =F5+N5
A6: 4 | B6: =EDATE($B$2,A6) | C6: =F5 | D6: =C6*Ввод!$C$7 | E6: =IF(D6>0,D6*Ввод!$C$8,0) | F6: =C6+D6-E6 | G6: =Ввод!$C$5 | H6: =E6+G6 | I6: =I5*(1+Ввод!$F$20)+H6*Ввод!$C$12 | J6: =J5*(1+Ввод!$F$21)+H6*Ввод!$C$13 | K6: =K5*(1+Ввод!$F$22)+H6*Ввод!$C$14 | L6: =L5*(1+Ввод!$F$23)+H6*Ввод!$C$15 | M6: =M5*(1+Ввод!$F$24)+H6*Ввод!$C$16 | N6: =I6+J6+K6+L6+M6 | O6: =F6+N6
A7: 5 | B7: =EDATE($B$2,A7) | C7: =F6 | D7: =C7*Ввод!$C$7 | E7: =IF(D7>0,D7*Ввод!$C$8,0) | F7: =C7+D7-E7 | G7: =Ввод!$C$5 | H7: =E7+G7 | I7: =I6*(1+Ввод!$F$20)+H7*Ввод!$C$12 | J7: =J6*(1+Ввод!$F$21)+H7*Ввод!$C$13 | K7: =K6*(1+Ввод!$F$22)+H7*Ввод!$C$14 | L7: =L6*(1+Ввод!$F$23)+H7*Ввод!$C$15 | M7: =M6*(1+Ввод!$F$24)+H7*Ввод!$C$16 | N7: =I7+J7+K7+L7+M7 | O7: =F7+N7
A8: 6 | B8: =EDATE($B$2,A8) | C8: =F7 | D8: =C8*Ввод!$C$7 | E8: =IF(D8>0,D8*Ввод!$C$8,0) | F8: =C8+D8-E8 | G8: =Ввод!$C$5 | H8: =E8+G8 | I8: =I7*(1+Ввод!$F$20)+H8*Ввод!$C$12 | J8: =J7*(1+Ввод!$F$21)+H8*Ввод!$C$13 | K8: =K7*(1+Ввод!$F$22)+H8*Ввод!$C$14 | L8: =L7*(1+Ввод!$F$23)+H8*Ввод!$C$15 | M8: =M7*(1+Ввод!$F$24)+H8*Ввод!$C$16 | N8: =I8+J8+K8+L8+M8 | O8: =F8+N8
A9: 7 | B9: =EDATE($B$2,A9) | C9: =F8 | D9: =C9*Ввод!$C$7 | E9: =IF(D9>0,D9*Ввод!$C$8,0) | F9: =C9+D9-E9 | G9: =Ввод!$C$5 | H9: =E9+G9 | I9: =I8*(1+Ввод!$F$20)+H9*Ввод!$C$12 | J9: =J8*(1+Ввод!$F$21)+H9*Ввод!$C$13 | K9: =K8*(1+Ввод!$F$22)+H9*Ввод!$C$14 | L9: =L8*(1+Ввод!$F$23)+H9*Ввод!$C$15 | M9: =M8*(1+Ввод!$F$24)+H9*Ввод!$C$16 | N9: =I9+J9+K9+L9+M9 | O9: =F9+N9
A10: 8 | B10: =EDATE($B$2,A10) | C10: =F9 | D10: =C10*Ввод!$C$7 | E10: =IF(D10>0,D10*Ввод!$C$8,0) | F10: =C10+D10-E10 | G10: =Ввод!$C$5 | H10: =E10+G10 | I10: =I9*(1+Ввод!$F$20)+H10*Ввод!$C$12 | J10: =J9*(1+Ввод!$F$21)+H10*Ввод!$C$13 | K10: =K9*(1+Ввод!$F$22)+H10*Ввод!$C$14 | L10: =L9*(1+Ввод!$F$23)+H10*Ввод!$C$15 | M10: =M9*(1+Ввод!$F$24)+H10*Ввод!$C$16 | N10: =I10+J10+K10+L10+M10 | O10: =F10+N10
A11: 9 | B11: =EDATE($B$2,A11) | C11: =F10 | D11: =C11*Ввод!$C$7 | E11: =IF(D11>0,D11*Ввод!$C$8,0) | F11: =C11+D11-E11 | G11: =Ввод!$C$5 | H11: =E11+G11 | I11: =I10*(1+Ввод!$F$20)+H11*Ввод!$C$12 | J11: =J10*(1+Ввод!$F$21)+H11*Ввод!$C$13 | K11: =K10*(1+Ввод!$F$22)+H11*Ввод!$C$14 | L11: =L10*(1+Ввод!$F$23)+H11*Ввод!$C$15 | M11: =M10*(1+Ввод!$F$24)+H11*Ввод!$C$16 | N11: =I11+J11+K11+L11+M11 | O11: =F11+N11
A12: 10 | B12: =EDATE($B$2,A12) | C12: =F11 | D12: =C12*Ввод!$C$7 | E12: =IF(D12>0,D12*Ввод!$C$8,0) | F12: =C12+D12-E12 | G12: =Ввод!$C$5 | H12: =E12+G12 | I12: =I11*(1+Ввод!$F$20)+H12*Ввод!$C$12 | J12: =J11*(1+Ввод!$F$21)+H12*Ввод!$C$13 | K12: =K11*(1+Ввод!$F$22)+H12*Ввод!$C$14 | L12: =L11*(1+Ввод!$F$23)+H12*Ввод!$C$15 | M12: =M11*(1+Ввод!$F$24)+H12*Ввод!$C$16 | N12: =I12+J12+K12+L12+M12 | O12: =F12+N12
A13: 11 | B13: =EDATE($B$2,A13) | C13: =F12 | D13: =C13*Ввод!$C$7 | E13: =IF(D13>0,D13*Ввод!$C$8,0) | F13: =C13+D13-E13 | G13: =Ввод!$C$5 | H13: =E13+G13 | I13: =I12*(1+Ввод!$F$20)+H13*Ввод!$C$12 | J13: =J12*(1+Ввод!$F$21)+H13*Ввод!$C$13 | K13: =K12*(1+Ввод!$F$22)+H13*Ввод!$C$14 | L13: =L12*(1+Ввод!$F$23)+H13*Ввод!$C$15 | M13: =M12*(1+Ввод!$F$24)+H13*Ввод!$C$16 | N13: =I13+J13+K13+L13+M13 | O13: =F13+N13
A14: 12 | B14: =EDATE($B$2,A14) | C14: =F13 | D14: =C14*Ввод!$C$7 | E14: =IF(D14>0,D14*Ввод!$C$8,0) | F14: =C14+D14-E14 | G14: =Ввод!$C$5 | H14: =E14+G14 | I14: =I13*(1+Ввод!$F$20)+H14*Ввод!$C$12 | J14: =J13*(1+Ввод!$F$21)+H14*Ввод!$C$13 | K14: =K13*(1+Ввод!$F$22)+H14*Ввод!$C$14 | L14: =L13*(1+Ввод!$F$23)+H14*Ввод!$C$15 | M14: =M13*(1+Ввод!$F$24)+H14*Ввод!$C$16 | N14: =I14+J14+K14+L14+M14 | O14: =F14+N14
... A26: 24 | B26: =EDATE($B$2,A26) | C26: =F25 | D26: =C26*Ввод!$C$7 | E26: =IF(D26>0,D26*Ввод!$C$8,0) | F26: =C26+D26-E26 | G26: =Ввод!$C$5 | H26: =E26+G26 | I26: =I25*(1+Ввод!$F$20)+H26*Ввод!$C$12 | J26: =J25*(1+Ввод!$F$21)+H26*Ввод!$C$13 | K26: =K25*(1+Ввод!$F$22)+H26*Ввод!$C$14 | L26: =L25*(1+Ввод!$F$23)+H26*Ввод!$C$15 | M26: =M25*(1+Ввод!$F$24)+H26*Ввод!$C$16 | N26: =I26+J26+K26+L26+M26 | O26: =F26+N26

Sheet Пояснение
A1: Как читать таблицу
A3: Жёлтые ячейки на листе «Ввод» — это ручки. Поменял прибыль бота — все 24 месяца и итог пересчитались.
A5: Бот. На старте 100 000 ₽ целиком на торговом счёте. Прибыль считается от суммы на начало месяца. Если прибыль плюс — снимаем долю (обычно 20%). Остальное остаётся на боте, объём растёт. Если месяц в минусе — с бота ничего не снимаем, счёт падает. 20 тысяч с работы всё равно кладём в портфель рядом.
A7: Портфель рядом. Сюда идут снятие с бота плюс отложенное с работы. Делим по долям. Сначала на уже лежащую сумму капает её процент за месяц, потом приходит новый взнос (в этом месяце он ещё не растёт).
A9: Почему такие доли по умолчанию. Вклад 40% — якорь. Облигации государства / фонды почти как вклад 15% — чуть гибче вклада. Акции 20% — рост, но прыгают. Золото 15% — страховка, если рубль слабеет. Биткоин 10% — сильный хвост, сильные просадки. Сайты с огромными процентами и займы незнакомцам сюда не кладём.
A11: Акции лучше фондом на индекс Мосбиржи (один пай), а не пятью случайными бумагами. Конкретные тикеры и цены — лист «Примеры сегодня».
A13: Это учебный расчёт при ровной прибыли, которую ты сам ставишь. Это не прогноз бота и не совет купить бумагу.
A15: Связанные файлы проекта: docs/analiz-xiaomi-su7-24m.md, docs/fuchersy-bot.md, docs/obzor.html.

Sheet Примеры сегодня
A1: Если решение принимаешь сегодня: цены и примеры
A2: Срез 1 сентября 2026. Это ориентиры для первой покупки, не приказ брокеру. Перед сделкой открой стакан на Мосбирже: цена за день меняется. Это не индивидуальная рекомендация.
A4: Рынок вокруг копилки
A5: Что | B5: Цифра | C5: Откуда / зачем
A6: Дата среза | B6: 1 сентября 2026 | C6: Календарь проекта
A7: Ключевая ставка Банка России | B7: 14% | C7: С 27 июля 2026, заседание 11 сентября 2026
A8: Доллар к рублю | B8: 86,3793 ₽ | C8: Банк России, 01.09.2026
A9: Юань к рублю | B9: 12,8580 ₽ | C9: Банк России, 01.09.2026
A10: Биткоин | B10: 78 121 $ ≈ 6,78 млн ₽ | C10: рынок, ориентир на дату сбора таблицы
A11: Золото, учётная цена Банка России | B11: 12 671,47 ₽ за грамм | C11: с 1 сентября 2026, +97,15 ₽ к предыдущей
A12: Серебро, учётная цена Банка России | B12: 195,12 ₽ за грамм | C12: с 1 сентября 2026
A13: Индекс Мосбиржи, ориентир конца августа | B13: около 2 115 пунктов | C13: неделя 24–28 августа 2026, −0,9%
A14: Вклады на 3–12 месяцев | B14: около 13–15% | C14: как в разборе проекта
A15: Фонды денежного рынка (LQDT, AKMM и похожие) | B15: около 14% годовых | C15: близко к ключевой ставке, не вклад
A16: ОФЗ, доходность к погашению, ориентир лета | B16: около 15% | C16: цена бумаги прыгает, если ставка изменится
A18: Одна корзина, если решение принимаешь сегодня
A19: Первый месяц при настройках листа «Ввод»: с работы 20 000 ₽ + сняли с бота 1 000 ₽ = 21 000 ₽ в портфель рядом. Ниже — конкретная покупка на эти 21 000. Перед сделкой сверь цену в стакане.
A21: Доля | B21: Куда | C21: Что купить сегодня | D21: Ориентир | E21: На сколько | F21: Что получится
A22: 40% | B22: Спокойный вклад | C22: Вклад 3–12 месяцев в крупном банке (в пределах страховки) | D22: 13–15% годовых | E22: 8 400 ₽ | F22: Без лота: кладёшь всю сумму
A23: 15% | B23: Почти как вклад | C23: Паи денежного рынка: LQDT, AKMM или SBMM — если не хочешь открывать вклад каждый месяц | D23: около ключевой 14% | E23: 3 150 ₽ | F23: Паи на всю сумму 3 150 ₽
A24: 20% | B24: Акции | C24: Один фонд на индекс Мосбиржи: TMOS (запасной тот же смысл — SBMX или EQMX) | D24: TMOS 5,21 ₽ (27.08.2026) | E24: 4 200 ₽ | F24: около 800 паёв TMOS. Не 15 разных компаний руками
A25: 15% | B25: Золото | C25: Фонд золота: TGLD, GOLD, SBGD или AKGD. Не слиток | D25: учёт Банка России 12 671,47 ₽/г | E25: 3 150 ₽ | F25: паи на 3 150 ₽. Грамм слитка дороже всего этого куска
A26: 10% | B26: Биткоин вне бота | C26: Купить без займа и не трогать. Это не торговый счёт бота | D26: 78 121 $ ≈ 6,78 млн ₽ за 1 BTC | E26: 2 100 ₽ | F26: ≈ 0,00031 BTC
A28: Как купить золото на эту сумму
A29: На лист «Ввод» в золото по умолчанию идёт 15% новых взносов. В первый месяц при боте 5% это примерно: прибыль бота 5 000 ₽, сняли 1 000 ₽, с работы 20 000 ₽, всего в портфель 21 000 ₽, в золото ≈ 3 150 ₽.
A31: Как | B31: Тикер / что | C31: Ориентир цены | D31: На ≈ 3 150 ₽ | E31: Плюс | F31: Минус
A32: Проще всего | B32: Фонд золота на Мосбирже: TGLD, GOLD, SBGD, AKGD | C32: смотри пай в стакане | D32: паи на всю сумму 3 150 ₽ | E32: не надо хранить слиток, можно продать в биржевой день | F32: комиссия фонда, цена зависит от металла и рубля
A33: Слиток / монета | B33: золото 999 пробы | C33: 12 671 ₽/г по Банку России | D33: на 3 150 ₽ даже 1 грамм не купить (нужно ≈ 12 700 ₽ на грамм) | E33: физический металл | F33: спред банка, хранение. Имеет смысл, когда в золоте уже десятки тысяч
A34: 10 грамм | B34: мерный слиток | C34: ≈ 126 715 ₽ без спреда | D34: не в первый месяц | E34: понятная штука | F34: дорого относительно ежемесячного взноса
A36: Акции компаний: если решаешь сегодня
A37: Главный совет таблицы: не собирать «пять любимых бумаг» на 4 000 ₽ в месяц. Купи один биржевой фонд на индекс Мосбиржи — внутри уже Сбер, Лукойл, нефть, банки. Ниже — если всё же хочешь видеть конкретные имена. Фонд за год к концу августа 2026 был в минусе примерно на 20% — акции прыгают.
A39: Приоритет | B39: Что купить | C39: Тикер | D39: Ориентир цены | E39: Дата цены | F39: На ≈ 4 200 ₽ (20% первого взноса) | G39: Зачем в копилку на машину
A40: 1. Лучше так | B40: Фонд «индекс Мосбиржи», дивиденды внутри пая | C40: TMOS | D40: 5,21 ₽ за пай | E40: 27.08.2026 | F40: около 800 паёв | G40: Одна покупка, внутри много компаний. Расходы фонда около 0,8% в год.
A41: 1. Тот же смысл | B41: Фонд «топ российских акций» | C41: SBMX | D41: 15,13 ₽ за пай | E41: 20.08.2026 | F41: около 277 паёв | G41: Крупный фонд. За год к этой дате пай был примерно −22%.
A42: 1. Тот же смысл | B42: Фонд «индекс Мосбиржи» | C42: EQMX | D42: 115,60 ₽ за пай | E42: 20.08.2026 | F42: 36 паёв (чуть останется сдача) | G42: Дороже пай — меньше штук. Смысл тот же: индекс, не ставка на одну фирму.
A43: 2. Если очень хочешь одну бумагу | B43: Сбербанк, обыкновенные | C43: SBER | D43: 275,85 ₽ | E43: 01.09.2026 | F43: 15 акций ≈ 4 138 ₽ | G43: Самая ликвидная акция. Банк зарабатывает при высокой ставке, но цена прыгает вместе с рынком.
A44: 2. Не вместо фонда, а понимание индекса | B44: Лукойл | C44: LKOH | D44: 4 324 ₽ | E44: конец августа 2026 | F44: 1 акция ≈ 4 324 ₽ (весь кусок акций уйдёт в одну бумагу) | G44: Большая нефтяная компания, часто в топе индекса. Одна акция дорогая: на месячный взнос едва хватает штуки.
A45: Не база | B45: Не класть всё в одну нефтяную или одну «историю» | C45: — | D45: — | E45: — | F45: — | G45: Для цели «машина через 2 года» важнее не угадать тикер, а не сжечь копилку. Индекс спокойнее эго.
A47: Биткоин вне бота (10% новых взносов ≈ 2 100 ₽ в первый месяц при 5% бота)
A48: Где | B48: Цена среза | C48: На 2 100 ₽ | D48: Как не спутать с ботом
...
